[2025-05-05T09:29:49.104+0000] {local_task_job_runner.py:120} INFO - ::group::Pre task execution logs
[2025-05-05T09:29:49.118+0000] {taskinstance.py:2076} INFO - Dependencies all met for dep_context=non-requeueable deps ti=<TaskInstance: dbt_iceberg_example.insert_data_into_trino scheduled__2025-05-04T00:00:00+00:00 [queued]>
[2025-05-05T09:29:49.123+0000] {taskinstance.py:2076} INFO - Dependencies all met for dep_context=requeueable deps ti=<TaskInstance: dbt_iceberg_example.insert_data_into_trino scheduled__2025-05-04T00:00:00+00:00 [queued]>
[2025-05-05T09:29:49.123+0000] {taskinstance.py:2306} INFO - Starting attempt 1 of 3
[2025-05-05T09:29:49.133+0000] {taskinstance.py:2330} INFO - Executing <Task(PythonOperator): insert_data_into_trino> on 2025-05-04 00:00:00+00:00
[2025-05-05T09:29:49.138+0000] {standard_task_runner.py:63} INFO - Started process 84 to run task
[2025-05-05T09:29:49.140+0000] {standard_task_runner.py:90} INFO - Running: ['***', 'tasks', 'run', 'dbt_iceberg_example', 'insert_data_into_trino', 'scheduled__2025-05-04T00:00:00+00:00', '--job-id', '95', '--raw', '--subdir', 'DAGS_FOLDER/dbt_iceberg_dag.py', '--cfg-path', '/tmp/tmpmqe7u08e']
[2025-05-05T09:29:49.141+0000] {standard_task_runner.py:91} INFO - Job 95: Subtask insert_data_into_trino
[2025-05-05T09:29:49.172+0000] {task_command.py:426} INFO - Running <TaskInstance: dbt_iceberg_example.insert_data_into_trino scheduled__2025-05-04T00:00:00+00:00 [running]> on host 27fc0593f179
[2025-05-05T09:29:49.219+0000] {taskinstance.py:2648} INFO - Exporting env vars: AIRFLOW_CTX_DAG_OWNER='***' AIRFLOW_CTX_DAG_ID='dbt_iceberg_example' AIRFLOW_CTX_TASK_ID='insert_data_into_trino' AIRFLOW_CTX_EXECUTION_DATE='2025-05-04T00:00:00+00:00' AIRFLOW_CTX_TRY_NUMBER='1' AIRFLOW_CTX_DAG_RUN_ID='scheduled__2025-05-04T00:00:00+00:00'
[2025-05-05T09:29:49.220+0000] {taskinstance.py:430} INFO - ::endgroup::
[2025-05-05T09:29:52.301+0000] {client.py:892} INFO - failed after 3 attempts
[2025-05-05T09:29:52.301+0000] {logging_mixin.py:188} INFO - Erro ao inserir dados: failed to fetch: HTTPConnectionPool(host='trino', port=8080): Max retries exceeded with url: /v1/statement/queued/20250505_092951_00004_tjx7t/y2a2cd0a8be479045b8a1f0fb39e7626adb09415e/2 (Caused by NewConnectionError('<urllib3.connection.HTTPConnection object at 0x7ff3a201d9c0>: Failed to establish a new connection: [Errno 111] Connection refused'))
[2025-05-05T09:29:52.709+0000] {client.py:892} INFO - failed after 3 attempts
[2025-05-05T09:29:52.709+0000] {taskinstance.py:441} INFO - ::group::Post task execution logs
[2025-05-05T09:29:52.710+0000] {taskinstance.py:2905} ERROR - Task failed with exception
Traceback (most recent call last):
  File "/home/airflow/.local/lib/python3.10/site-packages/urllib3/connection.py", line 174, in _new_conn
    conn = connection.create_connection(
  File "/home/airflow/.local/lib/python3.10/site-packages/urllib3/util/connection.py", line 95, in create_connection
    raise err
  File "/home/airflow/.local/lib/python3.10/site-packages/urllib3/util/connection.py", line 85, in create_connection
    sock.connect(sa)
ConnectionRefusedError: [Errno 111] Connection refused

During handling of the above exception, another exception occurred:

Traceback (most recent call last):
  File "/home/airflow/.local/lib/python3.10/site-packages/urllib3/connectionpool.py", line 716, in urlopen
    httplib_response = self._make_request(
  File "/home/airflow/.local/lib/python3.10/site-packages/urllib3/connectionpool.py", line 416, in _make_request
    conn.request(method, url, **httplib_request_kw)
  File "/home/airflow/.local/lib/python3.10/site-packages/urllib3/connection.py", line 244, in request
    super(HTTPConnection, self).request(method, url, body=body, headers=headers)
  File "/usr/local/lib/python3.10/http/client.py", line 1283, in request
    self._send_request(method, url, body, headers, encode_chunked)
  File "/usr/local/lib/python3.10/http/client.py", line 1329, in _send_request
    self.endheaders(body, encode_chunked=encode_chunked)
  File "/usr/local/lib/python3.10/http/client.py", line 1278, in endheaders
    self._send_output(message_body, encode_chunked=encode_chunked)
  File "/usr/local/lib/python3.10/http/client.py", line 1038, in _send_output
    self.send(msg)
  File "/usr/local/lib/python3.10/http/client.py", line 976, in send
    self.connect()
  File "/home/airflow/.local/lib/python3.10/site-packages/urllib3/connection.py", line 205, in connect
    conn = self._new_conn()
  File "/home/airflow/.local/lib/python3.10/site-packages/urllib3/connection.py", line 186, in _new_conn
    raise NewConnectionError(
urllib3.exceptions.NewConnectionError: <urllib3.connection.HTTPConnection object at 0x7ff3a201d9c0>: Failed to establish a new connection: [Errno 111] Connection refused

During handling of the above exception, another exception occurred:

Traceback (most recent call last):
  File "/home/airflow/.local/lib/python3.10/site-packages/requests/adapters.py", line 486, in send
    resp = conn.urlopen(
  File "/home/airflow/.local/lib/python3.10/site-packages/urllib3/connectionpool.py", line 802, in urlopen
    retries = retries.increment(
  File "/home/airflow/.local/lib/python3.10/site-packages/urllib3/util/retry.py", line 594, in increment
    raise MaxRetryError(_pool, url, error or ResponseError(cause))
urllib3.exceptions.MaxRetryError: HTTPConnectionPool(host='trino', port=8080): Max retries exceeded with url: /v1/statement/queued/20250505_092951_00004_tjx7t/y2a2cd0a8be479045b8a1f0fb39e7626adb09415e/2 (Caused by NewConnectionError('<urllib3.connection.HTTPConnection object at 0x7ff3a201d9c0>: Failed to establish a new connection: [Errno 111] Connection refused'))

During handling of the above exception, another exception occurred:

Traceback (most recent call last):
  File "/home/airflow/.local/lib/python3.10/site-packages/trino/client.py", line 827, in fetch
    response = self._request.get(self._request.next_uri)
  File "/home/airflow/.local/lib/python3.10/site-packages/trino/client.py", line 565, in get
    return self._get(
  File "/home/airflow/.local/lib/python3.10/site-packages/trino/client.py", line 894, in decorated
    raise error
  File "/home/airflow/.local/lib/python3.10/site-packages/trino/client.py", line 881, in decorated
    result = func(*args, **kwargs)
  File "/home/airflow/.local/lib/python3.10/site-packages/requests/sessions.py", line 602, in get
    return self.request("GET", url, **kwargs)
  File "/home/airflow/.local/lib/python3.10/site-packages/requests/sessions.py", line 589, in request
    resp = self.send(prep, **send_kwargs)
  File "/home/airflow/.local/lib/python3.10/site-packages/requests/sessions.py", line 703, in send
    r = adapter.send(request, **kwargs)
  File "/home/airflow/.local/lib/python3.10/site-packages/requests/adapters.py", line 519, in send
    raise ConnectionError(e, request=request)
requests.exceptions.ConnectionError: HTTPConnectionPool(host='trino', port=8080): Max retries exceeded with url: /v1/statement/queued/20250505_092951_00004_tjx7t/y2a2cd0a8be479045b8a1f0fb39e7626adb09415e/2 (Caused by NewConnectionError('<urllib3.connection.HTTPConnection object at 0x7ff3a201d9c0>: Failed to establish a new connection: [Errno 111] Connection refused'))

During handling of the above exception, another exception occurred:

Traceback (most recent call last):
  File "/opt/airflow/dags/dbt_iceberg_dag.py", line 161, in insert_data_into_trino
    cursor.execute("DELETE FROM iceberg.raw.sales")
  File "/home/airflow/.local/lib/python3.10/site-packages/trino/dbapi.py", line 592, in execute
    self._iterator = iter(self._query.execute())
  File "/home/airflow/.local/lib/python3.10/site-packages/trino/client.py", line 810, in execute
    self._result.rows += self.fetch()
  File "/home/airflow/.local/lib/python3.10/site-packages/trino/client.py", line 829, in fetch
    raise trino.exceptions.TrinoConnectionError("failed to fetch: {}".format(e))
trino.exceptions.TrinoConnectionError: failed to fetch: HTTPConnectionPool(host='trino', port=8080): Max retries exceeded with url: /v1/statement/queued/20250505_092951_00004_tjx7t/y2a2cd0a8be479045b8a1f0fb39e7626adb09415e/2 (Caused by NewConnectionError('<urllib3.connection.HTTPConnection object at 0x7ff3a201d9c0>: Failed to establish a new connection: [Errno 111] Connection refused'))

During handling of the above exception, another exception occurred:

Traceback (most recent call last):
  File "/home/airflow/.local/lib/python3.10/site-packages/trino/client.py", line 848, in cancel
    response = self._request.delete(self._next_uri)
  File "/home/airflow/.local/lib/python3.10/site-packages/trino/client.py", line 573, in delete
    return self._delete(url, timeout=self._request_timeout, proxies=PROXIES)
  File "/home/airflow/.local/lib/python3.10/site-packages/trino/client.py", line 894, in decorated
    raise error
  File "/home/airflow/.local/lib/python3.10/site-packages/trino/client.py", line 881, in decorated
    result = func(*args, **kwargs)
  File "/home/airflow/.local/lib/python3.10/site-packages/requests/sessions.py", line 671, in delete
    return self.request("DELETE", url, **kwargs)
  File "/home/airflow/.local/lib/python3.10/site-packages/requests/sessions.py", line 589, in request
    resp = self.send(prep, **send_kwargs)
  File "/home/airflow/.local/lib/python3.10/site-packages/requests/sessions.py", line 703, in send
    r = adapter.send(request, **kwargs)
  File "/home/airflow/.local/lib/python3.10/site-packages/requests/adapters.py", line 519, in send
    raise ConnectionError(e, request=request)
requests.exceptions.ConnectionError: HTTPConnectionPool(host='trino', port=8080): Max retries exceeded with url: /v1/statement/queued/20250505_092951_00004_tjx7t/y2a2cd0a8be479045b8a1f0fb39e7626adb09415e/2 (Caused by NewConnectionError('<urllib3.connection.HTTPConnection object at 0x7ff3a201ead0>: Failed to establish a new connection: [Errno 111] Connection refused'))

During handling of the above exception, another exception occurred:

Traceback (most recent call last):
  File "/home/airflow/.local/lib/python3.10/site-packages/airflow/models/taskinstance.py", line 465, in _execute_task
    result = _execute_callable(context=context, **execute_callable_kwargs)
  File "/home/airflow/.local/lib/python3.10/site-packages/airflow/models/taskinstance.py", line 432, in _execute_callable
    return execute_callable(context=context, **execute_callable_kwargs)
  File "/home/airflow/.local/lib/python3.10/site-packages/airflow/models/baseoperator.py", line 400, in wrapper
    return func(self, *args, **kwargs)
  File "/home/airflow/.local/lib/python3.10/site-packages/airflow/operators/python.py", line 235, in execute
    return_value = self.execute_callable()
  File "/home/airflow/.local/lib/python3.10/site-packages/airflow/operators/python.py", line 252, in execute_callable
    return self.python_callable(*self.op_args, **self.op_kwargs)
  File "/opt/airflow/dags/dbt_iceberg_dag.py", line 203, in insert_data_into_trino
    cursor.close()
  File "/home/airflow/.local/lib/python3.10/site-packages/trino/dbapi.py", line 709, in close
    self.cancel()
  File "/home/airflow/.local/lib/python3.10/site-packages/trino/dbapi.py", line 706, in cancel
    self._query.cancel()
  File "/home/airflow/.local/lib/python3.10/site-packages/trino/client.py", line 850, in cancel
    raise trino.exceptions.TrinoConnectionError("failed to cancel query: {}".format(e))
trino.exceptions.TrinoConnectionError: failed to cancel query: HTTPConnectionPool(host='trino', port=8080): Max retries exceeded with url: /v1/statement/queued/20250505_092951_00004_tjx7t/y2a2cd0a8be479045b8a1f0fb39e7626adb09415e/2 (Caused by NewConnectionError('<urllib3.connection.HTTPConnection object at 0x7ff3a201ead0>: Failed to establish a new connection: [Errno 111] Connection refused'))
[2025-05-05T09:29:52.724+0000] {taskinstance.py:1206} INFO - Marking task as UP_FOR_RETRY. dag_id=dbt_iceberg_example, task_id=insert_data_into_trino, run_id=scheduled__2025-05-04T00:00:00+00:00, execution_date=20250504T000000, start_date=20250505T092949, end_date=20250505T092952
[2025-05-05T09:29:52.732+0000] {standard_task_runner.py:110} ERROR - Failed to execute job 95 for task insert_data_into_trino (failed to cancel query: HTTPConnectionPool(host='trino', port=8080): Max retries exceeded with url: /v1/statement/queued/20250505_092951_00004_tjx7t/y2a2cd0a8be479045b8a1f0fb39e7626adb09415e/2 (Caused by NewConnectionError('<urllib3.connection.HTTPConnection object at 0x7ff3a201ead0>: Failed to establish a new connection: [Errno 111] Connection refused')); 84)
[2025-05-05T09:29:52.763+0000] {local_task_job_runner.py:240} INFO - Task exited with return code 1
[2025-05-05T09:29:52.763+0000] {local_task_job_runner.py:222} INFO - ::endgroup::
[2025-05-05T09:52:28.627+0000] {local_task_job_runner.py:120} INFO - ::group::Pre task execution logs
[2025-05-05T09:52:28.641+0000] {taskinstance.py:2076} INFO - Dependencies all met for dep_context=non-requeueable deps ti=<TaskInstance: dbt_iceberg_example.insert_data_into_trino scheduled__2025-05-04T00:00:00+00:00 [queued]>
[2025-05-05T09:52:28.646+0000] {taskinstance.py:2076} INFO - Dependencies all met for dep_context=requeueable deps ti=<TaskInstance: dbt_iceberg_example.insert_data_into_trino scheduled__2025-05-04T00:00:00+00:00 [queued]>
[2025-05-05T09:52:28.646+0000] {taskinstance.py:2306} INFO - Starting attempt 1 of 3
[2025-05-05T09:52:28.653+0000] {taskinstance.py:2330} INFO - Executing <Task(PythonOperator): insert_data_into_trino> on 2025-05-04 00:00:00+00:00
[2025-05-05T09:52:28.658+0000] {standard_task_runner.py:63} INFO - Started process 169 to run task
[2025-05-05T09:52:28.660+0000] {standard_task_runner.py:90} INFO - Running: ['***', 'tasks', 'run', 'dbt_iceberg_example', 'insert_data_into_trino', 'scheduled__2025-05-04T00:00:00+00:00', '--job-id', '12', '--raw', '--subdir', 'DAGS_FOLDER/dbt_iceberg_dag.py', '--cfg-path', '/tmp/tmpb7d9_oyn']
[2025-05-05T09:52:28.661+0000] {standard_task_runner.py:91} INFO - Job 12: Subtask insert_data_into_trino
[2025-05-05T09:52:28.686+0000] {task_command.py:426} INFO - Running <TaskInstance: dbt_iceberg_example.insert_data_into_trino scheduled__2025-05-04T00:00:00+00:00 [running]> on host 92b88004addd
[2025-05-05T09:52:28.735+0000] {taskinstance.py:2648} INFO - Exporting env vars: AIRFLOW_CTX_DAG_OWNER='***' AIRFLOW_CTX_DAG_ID='dbt_iceberg_example' AIRFLOW_CTX_TASK_ID='insert_data_into_trino' AIRFLOW_CTX_EXECUTION_DATE='2025-05-04T00:00:00+00:00' AIRFLOW_CTX_TRY_NUMBER='1' AIRFLOW_CTX_DAG_RUN_ID='scheduled__2025-05-04T00:00:00+00:00'
[2025-05-05T09:52:28.736+0000] {taskinstance.py:430} INFO - ::endgroup::
[2025-05-05T09:52:29.009+0000] {dbapi.py:285} WARNING - EXECUTE IMMEDIATE not available for trino:8080; defaulting to legacy prepared statements (TrinoUserError(type=USER_ERROR, name=SYNTAX_ERROR, message="line 1:19: mismatched input ''SELECT 1''. Expecting: 'USING', <EOF>", query_id=20250505_095224_00065_b4a46))
[2025-05-05T09:52:31.338+0000] {logging_mixin.py:188} INFO - Dados inseridos com sucesso nas tabelas Iceberg
[2025-05-05T09:52:31.340+0000] {python.py:237} INFO - Done. Returned value was: None
[2025-05-05T09:52:31.341+0000] {taskinstance.py:441} INFO - ::group::Post task execution logs
[2025-05-05T09:52:31.347+0000] {taskinstance.py:1206} INFO - Marking task as SUCCESS. dag_id=dbt_iceberg_example, task_id=insert_data_into_trino, run_id=scheduled__2025-05-04T00:00:00+00:00, execution_date=20250504T000000, start_date=20250505T095228, end_date=20250505T095231
[2025-05-05T09:52:31.397+0000] {local_task_job_runner.py:240} INFO - Task exited with return code 0
[2025-05-05T09:52:31.397+0000] {local_task_job_runner.py:222} INFO - ::endgroup::
