[2025-05-04T19:25:28.862+0000] {local_task_job_runner.py:120} INFO - ::group::Pre task execution logs
[2025-05-04T19:25:28.874+0000] {taskinstance.py:2076} INFO - Dependencies all met for dep_context=non-requeueable deps ti=<TaskInstance: dbt_iceberg_example.insert_data_into_trino manual__2025-05-04T19:25:25.558516+00:00 [queued]>
[2025-05-04T19:25:28.878+0000] {taskinstance.py:2076} INFO - Dependencies all met for dep_context=requeueable deps ti=<TaskInstance: dbt_iceberg_example.insert_data_into_trino manual__2025-05-04T19:25:25.558516+00:00 [queued]>
[2025-05-04T19:25:28.879+0000] {taskinstance.py:2306} INFO - Starting attempt 1 of 2
[2025-05-04T19:25:28.886+0000] {taskinstance.py:2330} INFO - Executing <Task(PythonOperator): insert_data_into_trino> on 2025-05-04 19:25:25.558516+00:00
[2025-05-04T19:25:28.890+0000] {standard_task_runner.py:63} INFO - Started process 1292 to run task
[2025-05-04T19:25:28.892+0000] {standard_task_runner.py:90} INFO - Running: ['***', 'tasks', 'run', 'dbt_iceberg_example', 'insert_data_into_trino', 'manual__2025-05-04T19:25:25.558516+00:00', '--job-id', '82', '--raw', '--subdir', 'DAGS_FOLDER/dbt_iceberg_dag.py', '--cfg-path', '/tmp/tmptauday7l']
[2025-05-04T19:25:28.892+0000] {standard_task_runner.py:91} INFO - Job 82: Subtask insert_data_into_trino
[2025-05-04T19:25:28.917+0000] {task_command.py:426} INFO - Running <TaskInstance: dbt_iceberg_example.insert_data_into_trino manual__2025-05-04T19:25:25.558516+00:00 [running]> on host 27fc0593f179
[2025-05-04T19:25:28.962+0000] {taskinstance.py:2648} INFO - Exporting env vars: AIRFLOW_CTX_DAG_OWNER='***' AIRFLOW_CTX_DAG_ID='dbt_iceberg_example' AIRFLOW_CTX_TASK_ID='insert_data_into_trino' AIRFLOW_CTX_EXECUTION_DATE='2025-05-04T19:25:25.558516+00:00' AIRFLOW_CTX_TRY_NUMBER='1' AIRFLOW_CTX_DAG_RUN_ID='manual__2025-05-04T19:25:25.558516+00:00'
[2025-05-04T19:25:28.963+0000] {taskinstance.py:430} INFO - ::endgroup::
[2025-05-04T19:25:29.138+0000] {dbapi.py:285} WARNING - EXECUTE IMMEDIATE not available for trino:8080; defaulting to legacy prepared statements (TrinoUserError(type=USER_ERROR, name=SYNTAX_ERROR, message="line 1:19: mismatched input ''SELECT 1''. Expecting: 'USING', <EOF>", query_id=20250504_192202_00189_scynm))
[2025-05-04T19:25:29.166+0000] {logging_mixin.py:188} INFO - Erro ao inserir dados: TrinoUserError(type=USER_ERROR, name=TYPE_MISMATCH, message="Insert query has mismatched column types: Table: [integer, varchar, varchar, double, date], Query: [integer, varchar(9), varchar(11), double, varchar(10)]", query_id=20250504_192202_00191_scynm)
[2025-05-04T19:25:29.168+0000] {taskinstance.py:441} INFO - ::group::Post task execution logs
[2025-05-04T19:25:29.168+0000] {taskinstance.py:2905} ERROR - Task failed with exception
Traceback (most recent call last):
  File "/home/airflow/.local/lib/python3.10/site-packages/airflow/models/taskinstance.py", line 465, in _execute_task
    result = _execute_callable(context=context, **execute_callable_kwargs)
  File "/home/airflow/.local/lib/python3.10/site-packages/airflow/models/taskinstance.py", line 432, in _execute_callable
    return execute_callable(context=context, **execute_callable_kwargs)
  File "/home/airflow/.local/lib/python3.10/site-packages/airflow/models/baseoperator.py", line 400, in wrapper
    return func(self, *args, **kwargs)
  File "/home/airflow/.local/lib/python3.10/site-packages/airflow/operators/python.py", line 235, in execute
    return_value = self.execute_callable()
  File "/home/airflow/.local/lib/python3.10/site-packages/airflow/operators/python.py", line 252, in execute_callable
    return self.python_callable(*self.op_args, **self.op_kwargs)
  File "/opt/airflow/dags/dbt_iceberg_dag.py", line 165, in insert_data_into_trino
    cursor.execute(
  File "/home/airflow/.local/lib/python3.10/site-packages/trino/dbapi.py", line 578, in execute
    self._iterator = iter(self._query.execute())
  File "/home/airflow/.local/lib/python3.10/site-packages/trino/client.py", line 810, in execute
    self._result.rows += self.fetch()
  File "/home/airflow/.local/lib/python3.10/site-packages/trino/client.py", line 830, in fetch
    status = self._request.process(response)
  File "/home/airflow/.local/lib/python3.10/site-packages/trino/client.py", line 609, in process
    raise self._process_error(response["error"], response.get("id"))
trino.exceptions.TrinoUserError: TrinoUserError(type=USER_ERROR, name=TYPE_MISMATCH, message="Insert query has mismatched column types: Table: [integer, varchar, varchar, double, date], Query: [integer, varchar(9), varchar(11), double, varchar(10)]", query_id=20250504_192202_00191_scynm)
[2025-05-04T19:25:29.176+0000] {taskinstance.py:1206} INFO - Marking task as UP_FOR_RETRY. dag_id=dbt_iceberg_example, task_id=insert_data_into_trino, run_id=manual__2025-05-04T19:25:25.558516+00:00, execution_date=20250504T192525, start_date=20250504T192528, end_date=20250504T192529
[2025-05-04T19:25:29.183+0000] {standard_task_runner.py:110} ERROR - Failed to execute job 82 for task insert_data_into_trino (TrinoUserError(type=USER_ERROR, name=TYPE_MISMATCH, message="Insert query has mismatched column types: Table: [integer, varchar, varchar, double, date], Query: [integer, varchar(9), varchar(11), double, varchar(10)]", query_id=20250504_192202_00191_scynm); 1292)
[2025-05-04T19:25:29.224+0000] {local_task_job_runner.py:240} INFO - Task exited with return code 1
[2025-05-04T19:25:29.224+0000] {local_task_job_runner.py:222} INFO - ::endgroup::
