[2025-05-04T18:09:45.752+0000] {local_task_job_runner.py:120} INFO - ::group::Pre task execution logs
[2025-05-04T18:09:45.769+0000] {taskinstance.py:2076} INFO - Dependencies all met for dep_context=non-requeueable deps ti=<TaskInstance: dbt_iceberg_example.initialize_minio manual__2025-05-04T18:09:44.104591+00:00 [queued]>
[2025-05-04T18:09:45.775+0000] {taskinstance.py:2076} INFO - Dependencies all met for dep_context=requeueable deps ti=<TaskInstance: dbt_iceberg_example.initialize_minio manual__2025-05-04T18:09:44.104591+00:00 [queued]>
[2025-05-04T18:09:45.776+0000] {taskinstance.py:2306} INFO - Starting attempt 1 of 2
[2025-05-04T18:09:45.785+0000] {taskinstance.py:2330} INFO - Executing <Task(PythonOperator): initialize_minio> on 2025-05-04 18:09:44.104591+00:00
[2025-05-04T18:09:45.789+0000] {standard_task_runner.py:63} INFO - Started process 151 to run task
[2025-05-04T18:09:45.791+0000] {standard_task_runner.py:90} INFO - Running: ['***', 'tasks', 'run', 'dbt_iceberg_example', 'initialize_minio', 'manual__2025-05-04T18:09:44.104591+00:00', '--job-id', '37', '--raw', '--subdir', 'DAGS_FOLDER/dbt_iceberg_dag.py', '--cfg-path', '/tmp/tmpxglxaonb']
[2025-05-04T18:09:45.792+0000] {standard_task_runner.py:91} INFO - Job 37: Subtask initialize_minio
[2025-05-04T18:09:45.827+0000] {task_command.py:426} INFO - Running <TaskInstance: dbt_iceberg_example.initialize_minio manual__2025-05-04T18:09:44.104591+00:00 [running]> on host 27fc0593f179
[2025-05-04T18:09:45.879+0000] {taskinstance.py:2648} INFO - Exporting env vars: AIRFLOW_CTX_DAG_OWNER='***' AIRFLOW_CTX_DAG_ID='dbt_iceberg_example' AIRFLOW_CTX_TASK_ID='initialize_minio' AIRFLOW_CTX_EXECUTION_DATE='2025-05-04T18:09:44.104591+00:00' AIRFLOW_CTX_TRY_NUMBER='1' AIRFLOW_CTX_DAG_RUN_ID='manual__2025-05-04T18:09:44.104591+00:00'
[2025-05-04T18:09:45.880+0000] {taskinstance.py:430} INFO - ::endgroup::
[2025-05-04T18:09:46.430+0000] {taskinstance.py:441} INFO - ::group::Post task execution logs
[2025-05-04T18:09:46.431+0000] {taskinstance.py:2905} ERROR - Task failed with exception
Traceback (most recent call last):
  File "/opt/airflow/dags/dbt_iceberg_dag.py", line 44, in initialize_minio
    s3_client.head_bucket(Bucket='iceberg-data')
  File "/home/airflow/.local/lib/python3.10/site-packages/botocore/client.py", line 553, in _api_call
    return self._make_api_call(operation_name, kwargs)
  File "/home/airflow/.local/lib/python3.10/site-packages/botocore/client.py", line 1009, in _make_api_call
    raise error_class(parsed_response, operation_name)
botocore.exceptions.ClientError: An error occurred (404) when calling the HeadBucket operation: Not Found

During handling of the above exception, another exception occurred:

Traceback (most recent call last):
  File "/home/airflow/.local/lib/python3.10/site-packages/airflow/models/taskinstance.py", line 465, in _execute_task
    result = _execute_callable(context=context, **execute_callable_kwargs)
  File "/home/airflow/.local/lib/python3.10/site-packages/airflow/models/taskinstance.py", line 432, in _execute_callable
    return execute_callable(context=context, **execute_callable_kwargs)
  File "/home/airflow/.local/lib/python3.10/site-packages/airflow/models/baseoperator.py", line 400, in wrapper
    return func(self, *args, **kwargs)
  File "/home/airflow/.local/lib/python3.10/site-packages/airflow/operators/python.py", line 235, in execute
    return_value = self.execute_callable()
  File "/home/airflow/.local/lib/python3.10/site-packages/airflow/operators/python.py", line 252, in execute_callable
    return self.python_callable(*self.op_args, **self.op_kwargs)
  File "/opt/airflow/dags/dbt_iceberg_dag.py", line 47, in initialize_minio
    s3_client.create_bucket(Bucket='iceberg-data')
  File "/home/airflow/.local/lib/python3.10/site-packages/botocore/client.py", line 553, in _api_call
    return self._make_api_call(operation_name, kwargs)
  File "/home/airflow/.local/lib/python3.10/site-packages/botocore/client.py", line 1009, in _make_api_call
    raise error_class(parsed_response, operation_name)
botocore.errorfactory.BucketAlreadyOwnedByYou: An error occurred (BucketAlreadyOwnedByYou) when calling the CreateBucket operation: Your previous request to create the named bucket succeeded and you already own it.
[2025-05-04T18:09:46.441+0000] {taskinstance.py:1206} INFO - Marking task as UP_FOR_RETRY. dag_id=dbt_iceberg_example, task_id=initialize_minio, run_id=manual__2025-05-04T18:09:44.104591+00:00, execution_date=20250504T180944, start_date=20250504T180945, end_date=20250504T180946
[2025-05-04T18:09:46.449+0000] {standard_task_runner.py:110} ERROR - Failed to execute job 37 for task initialize_minio (An error occurred (BucketAlreadyOwnedByYou) when calling the CreateBucket operation: Your previous request to create the named bucket succeeded and you already own it.; 151)
[2025-05-04T18:09:46.485+0000] {local_task_job_runner.py:240} INFO - Task exited with return code 1
[2025-05-04T18:09:46.486+0000] {local_task_job_runner.py:222} INFO - ::endgroup::
